<?xml version="1.0" ?>
<!-- =================================================================================== -->
<!-- |    This document was autogenerated by xacro from src/scout_ros2/scout_description/urdf/scout_v2.xacro | -->
<!-- |    EDITING THIS FILE BY HAND IS NOT RECOMMENDED                                 | -->
<!-- =================================================================================== -->
<robot name="scout_v2">
  <material name="zed_mat">
    <color rgba="0.8 0.8 0.8 1.0"/>
  </material>
  <material name="zedm_mat">
    <color rgba="0 0 0 1.0"/>
  </material>
  <material name="zed2_mat">
    <color rgba="0.25 0.25 0.25 1.0"/>
  </material>
  <material name="zed2i_mat">
    <color rgba="0.25 0.25 0.25 1.0"/>
  </material>
  <material name="zedx_mat">
    <color rgba="0.25 0.25 0.25 1.0"/>
  </material>
  <material name="zedxm_mat">
    <color rgba="0.25 0.25 0.25 1.0"/>
  </material>
  <material name="zedxhdr_mat">
    <color rgba="0.25 0.25 0.25 1.0"/>
  </material>
  <material name="zedxhdrmini_mat">
    <color rgba="0.25 0.25 0.25 1.0"/>
  </material>
  <material name="zedxhdrmax_mat">
    <color rgba="0.25 0.25 0.25 1.0"/>
  </material>
  <material name="virtual_mat">
    <color rgba="0.25 0.25 0.25 1.0"/>
  </material>
  <material name="zedxonegs_mat">
    <color rgba="0.25 0.25 0.25 1.0"/>
  </material>
  <material name="zedxone4k_mat">
    <color rgba="0.25 0.25 0.25 1.0"/>
  </material>
  <material name="zedxonehdr_mat">
    <color rgba="0.25 0.25 0.25 1.0"/>
  </material>
  <!-- ====================== -->
  <!-- BASE LINK              -->
  <!-- ====================== -->
  <link name="base_link">
    <visual>
      <origin rpy="0 0 0" xyz="0 0 0"/>
      <geometry>
        <!-- Orijinal Scout 2.0 mesh -->
        <mesh filename="file:///home/diakamos/ros2_ws/install/scout_description/share/scout_description/meshes/base_link.dae"/>
      </geometry>
    </visual>
    <collision>
      <origin rpy="0 0 0" xyz="0 0 0.008"/>
      <geometry>
        <box size="0.925 0.38 0.21"/>
      </geometry>
    </collision>
    <collision>
      <origin rpy="0 0 0" xyz="0 0 0.034999999999999996"/>
      <geometry>
        <box size="0.15416666666666667 0.627 0.06999999999999999"/>
      </geometry>
    </collision>
  </link>
  <link name="inertial_link">
    <inertial>
      <mass value="50"/>
      <!-- Orijinal inertia değerlerin -->
      <origin xyz="0.0 0.0 0.0"/>
      <inertia ixx="2.288641" ixy="0" ixz="0" iyy="5.103976" iyz="0" izz="3.431465"/>
    </inertial>
  </link>
  <joint name="inertial_joint" type="fixed">
    <origin rpy="0 0 0" xyz="0 0 0"/>
    <parent link="base_link"/>
    <child link="inertial_link"/>
  </joint>
  <!-- ====================== -->
  <!-- ZED 2i KAMERA TANIMI   -->
  <!-- ====================== -->
  <!-- Camera mounting point (the threaded screw hole in the bottom) -->
  <link name="zed2i_camera_link"/>
  <!-- Camera Center -->
  <link name="zed2i_camera_center">
    <visual>
      <origin rpy="0 0 0" xyz="-0.01 0 0.0"/>
      <geometry>
        <mesh filename="file:///home/diakamos/ros2_ws/install/zed_msgs/share/zed_msgs/meshes/zed2i.stl"/>
      </geometry>
      <material name="zed2i_mat"/>
    </visual>
    <collision>
      <origin rpy="0 0 0" xyz="-0.01 0 0.0"/>
      <geometry>
        <mesh filename="file:///home/diakamos/ros2_ws/install/zed_msgs/share/zed_msgs/meshes/zed2i.stl"/>
      </geometry>
    </collision>
  </link>
  <joint name="zed2i_camera_center_joint" type="fixed">
    <parent link="zed2i_camera_link"/>
    <child link="zed2i_camera_center"/>
    <origin rpy="0 0.0 0" xyz="0 0 0.015"/>
  </joint>
  <!-- Left Camera -->
  <link name="zed2i_left_camera_frame">
  </link>
  <joint name="zed2i_left_camera_joint" type="fixed">
    <parent link="zed2i_camera_center"/>
    <child link="zed2i_left_camera_frame"/>
    <origin rpy="0 0 0" xyz="-0.01 0.06 0"/>
  </joint>
  <link name="zed2i_left_camera_optical_frame"/>
  <joint name="zed2i_left_camera_optical_joint" type="fixed">
    <origin rpy="-1.570795 0.0 -1.570795" xyz="0 0 0"/>
    <parent link="zed2i_left_camera_frame"/>
    <child link="zed2i_left_camera_optical_frame"/>
  </joint>
  <!-- Right Camera -->
  <link name="zed2i_right_camera_frame">
  </link>
  <joint name="zed2i_right_camera_joint" type="fixed">
    <parent link="zed2i_camera_center"/>
    <child link="zed2i_right_camera_frame"/>
    <origin rpy="0 0 0" xyz="-0.01 -0.06 0"/>
  </joint>
  <link name="zed2i_right_camera_optical_frame"/>
  <joint name="zed2i_right_camera_optical_joint" type="fixed">
    <origin rpy="-1.570795 0.0 -1.570795" xyz="0 0 0"/>
    <parent link="zed2i_right_camera_frame"/>
    <child link="zed2i_right_camera_optical_frame"/>
  </joint>
  <!-- ZED 2i kamerayı base_link'e sabitleyen eklem -->
  <joint name="zed2i_joint" type="fixed">
    <origin rpy="0 0 0" xyz="0.35 0.0 0.23"/>
    <parent link="base_link"/>
    <child link="zed2i_camera_link"/>
  </joint>
  <!-- ZED 2i için ekstra görsel link (aynı STL model) -->
  <link name="zed2i_visual_link">
    <visual>
      <origin rpy="0 0 0" xyz="0 0 0"/>
      <geometry>
        <!-- ZED paketindeki STL modelini paket yolu ile kullanıyoruz -->
        <mesh filename="package://zed_msgs/meshes/zed2i.stl" scale="1 1 1"/>
      </geometry>
    </visual>
  </link>
  <joint name="zed2i_visual_joint" type="fixed">
    <origin rpy="0 0 0" xyz="0 0 0"/>
    <!-- Kameranın fiziksel merkezi: macro’dan gelen link -->
    <parent link="zed2i_camera_center"/>
    <child link="zed2i_visual_link"/>
  </joint>
  <!-- ====================== -->
  <!-- 2D LiDAR LİNKLERİ      -->
  <!-- ====================== -->
  <!-- ÖN LiDAR -->
  <link name="front_lidar_link">
    <inertial>
      <mass value="0.01"/>
      <origin rpy="0 0 0" xyz="0 0 0"/>
      <inertia ixx="1e-6" ixy="0" ixz="0" iyy="1e-6" iyz="0" izz="1e-6"/>
    </inertial>
    <visual>
      <origin rpy="1.570795 0 0" xyz="0 0 0"/>
      <geometry>
        <!-- RP LIDAR STL (ugv_gazebo_sim/scout/scout_description/meshes/rp_lidar.stl) -->
        <mesh filename="file:///home/diakamos/ros2_ws/install/scout_description/share/scout_description/meshes/rp_lidar.stl" scale="0.0015 0.0015 0.0015"/>
      </geometry>
      <material name="lidar_gray">
        <color rgba="0.2 0.2 0.2 1.0"/>
      </material>
    </visual>
    <collision>
      <origin rpy="0 0 0" xyz="0 0 0"/>
      <geometry>
        <cylinder length="0.06" radius="0.04"/>
      </geometry>
    </collision>
  </link>
  <joint name="front_lidar_joint" type="fixed">
    <origin rpy="0 0 0" xyz="0.40 0.0 0.22"/>
    <parent link="base_link"/>
    <child link="front_lidar_link"/>
  </joint>
  <!-- ARKA LiDAR -->
  <link name="rear_lidar_link">
    <inertial>
      <mass value="0.01"/>
      <origin rpy="0 0 0" xyz="0 0 0"/>
      <inertia ixx="1e-6" ixy="0" ixz="0" iyy="1e-6" iyz="0" izz="1e-6"/>
    </inertial>
    <visual>
      <origin rpy="1.570795 0 0" xyz="0 0 0"/>
      <geometry>
        <mesh filename="file:///home/diakamos/ros2_ws/install/scout_description/share/scout_description/meshes/rp_lidar.stl" scale="0.0015 0.0015 0.0015"/>
      </geometry>
      <material name="lidar_gray">
        <color rgba="0.2 0.2 0.2 1.0"/>
      </material>
    </visual>
    <collision>
      <origin rpy="0 0 0" xyz="0 0 0"/>
      <geometry>
        <cylinder length="0.03" radius="0.04"/>
      </geometry>
    </collision>
  </link>
  <joint name="rear_lidar_joint" type="fixed">
    <origin rpy="0 0 3.14159" xyz="-0.40 0.0 0.22"/>
    <parent link="base_link"/>
    <child link="rear_lidar_link"/>
  </joint>
  <!-- ====================== -->
  <!-- TEKERLER               -->
  <!-- ====================== -->
  <link name="front_right_wheel_link">
    <inertial>
      <mass value="8"/>
      <origin xyz="0 0 0"/>
      <inertia ixx="0.1171" ixy="0" ixz="0" iyy="0.1361" iyz="0" izz="0.1171"/>
    </inertial>
    <visual>
      <origin rpy="0 0 0" xyz="0 0 0"/>
      <geometry>
        <mesh filename="file:///home/diakamos/ros2_ws/install/scout_description/share/scout_description/meshes/wheel_type1.dae"/>
      </geometry>
    </visual>
    <collision>
      <origin rpy="1.570795 0 0" xyz="0 0 0"/>
      <geometry>
        <cylinder length="0.11653" radius="0.16459"/>
      </geometry>
      <contact>
        <ode>
          <min_depth>0.001</min_depth>
        </ode>
      </contact>
    </collision>
  </link>
  <joint name="front_right_wheel" type="continuous">
    <parent link="base_link"/>
    <child link="front_right_wheel_link"/>
    <origin rpy="3.14 0 0" xyz="0.249 -0.29153 -0.0702"/>
    <axis rpy="0 0 0" xyz="0 -1 0"/>
    <dynamics damping="0.0" friction="20"/>
  </joint>
  <link name="front_left_wheel_link">
    <inertial>
      <mass value="8"/>
      <origin xyz="0 0 0"/>
      <inertia ixx="0.1171" ixy="0" ixz="0" iyy="0.1361" iyz="0" izz="0.1171"/>
    </inertial>
    <visual>
      <origin rpy="0 0 0" xyz="0 0 0"/>
      <geometry>
        <mesh filename="file:///home/diakamos/ros2_ws/install/scout_description/share/scout_description/meshes/wheel_type1.dae"/>
      </geometry>
    </visual>
    <collision>
      <origin rpy="1.570795 0 0" xyz="0 0 0"/>
      <geometry>
        <cylinder length="0.11653" radius="0.16459"/>
      </geometry>
      <contact>
        <ode>
          <min_depth>0.001</min_depth>
        </ode>
      </contact>
    </collision>
  </link>
  <joint name="front_left_wheel" type="continuous">
    <parent link="base_link"/>
    <child link="front_left_wheel_link"/>
    <origin rpy="0 0 0" xyz="0.249 0.29153 -0.0702"/>
    <axis rpy="0 0 0" xyz="0 1 0"/>
    <dynamics damping="0.0" friction="20"/>
  </joint>
  <link name="rear_left_wheel_link">
    <inertial>
      <mass value="8"/>
      <origin xyz="0 0 0"/>
      <inertia ixx="0.1171" ixy="0" ixz="0" iyy="0.1361" iyz="0" izz="0.1171"/>
    </inertial>
    <visual>
      <origin rpy="0 0 0" xyz="0 0 0"/>
      <geometry>
        <mesh filename="file:///home/diakamos/ros2_ws/install/scout_description/share/scout_description/meshes/wheel_type1.dae"/>
      </geometry>
    </visual>
    <collision>
      <origin rpy="1.570795 0 0" xyz="0 0 0"/>
      <geometry>
        <cylinder length="0.11653" radius="0.16459"/>
      </geometry>
      <contact>
        <ode>
          <min_depth>0.001</min_depth>
        </ode>
      </contact>
    </collision>
  </link>
  <joint name="rear_left_wheel" type="continuous">
    <parent link="base_link"/>
    <child link="rear_left_wheel_link"/>
    <origin rpy="0 0 0" xyz="-0.249 0.29153 -0.0702"/>
    <axis rpy="0 0 0" xyz="0 1 0"/>
    <dynamics damping="0.0" friction="20"/>
  </joint>
  <link name="rear_right_wheel_link">
    <inertial>
      <mass value="8"/>
      <origin xyz="0 0 0"/>
      <inertia ixx="0.1171" ixy="0" ixz="0" iyy="0.1361" iyz="0" izz="0.1171"/>
    </inertial>
    <visual>
      <origin rpy="0 0 0" xyz="0 0 0"/>
      <geometry>
        <mesh filename="file:///home/diakamos/ros2_ws/install/scout_description/share/scout_description/meshes/wheel_type1.dae"/>
      </geometry>
    </visual>
    <collision>
      <origin rpy="1.570795 0 0" xyz="0 0 0"/>
      <geometry>
        <cylinder length="0.11653" radius="0.16459"/>
      </geometry>
      <contact>
        <ode>
          <min_depth>0.001</min_depth>
        </ode>
      </contact>
    </collision>
  </link>
  <joint name="rear_right_wheel" type="continuous">
    <parent link="base_link"/>
    <child link="rear_right_wheel_link"/>
    <origin rpy="3.14 0 0" xyz="-0.249 -0.29153 -0.0702"/>
    <axis rpy="0 0 0" xyz="0 -1 0"/>
    <dynamics damping="0.0" friction="20"/>
  </joint>
  <!-- Boş ekstra URDF: şu an hiçbir ek link/joint yok -->
  <!-- Additional definitions for simulation -->
  <!-- <gazebo reference="base_link">
        <material>Gazebo/Grey</material>
    </gazebo> -->
  <transmission name="front_right_wheel_trans" type="SimpleTransmission">
    <type>transmission_interface/SimpleTransmission</type>
    <actuator name="front_right_wheel_motor">
      <mechanicalReduction>1</mechanicalReduction>
    </actuator>
    <joint name="front_right_wheel">
      <hardwareInterface>hardware_interface/VelocityJointInterface</hardwareInterface>
    </joint>
  </transmission>
  <transmission name="front_left_wheel_trans" type="SimpleTransmission">
    <type>transmission_interface/SimpleTransmission</type>
    <actuator name="front_left_wheel_motor">
      <mechanicalReduction>1</mechanicalReduction>
    </actuator>
    <joint name="front_left_wheel">
      <hardwareInterface>hardware_interface/VelocityJointInterface</hardwareInterface>
    </joint>
  </transmission>
  <transmission name="rear_left_wheel_trans" type="SimpleTransmission">
    <type>transmission_interface/SimpleTransmission</type>
    <actuator name="rear_left_wheel_motor">
      <mechanicalReduction>1</mechanicalReduction>
    </actuator>
    <joint name="rear_left_wheel">
      <hardwareInterface>hardware_interface/VelocityJointInterface</hardwareInterface>
    </joint>
  </transmission>
  <transmission name="rear_right_wheel_trans" type="SimpleTransmission">
    <type>transmission_interface/SimpleTransmission</type>
    <actuator name="rear_right_wheel_motor">
      <mechanicalReduction>1</mechanicalReduction>
    </actuator>
    <joint name="rear_right_wheel">
      <hardwareInterface>hardware_interface/VelocityJointInterface</hardwareInterface>
    </joint>
  </transmission>
  <!-- Controller configurations -->
  <!-- <gazebo>
        <plugin name="gazebo_ros_control" filename="libgazebo_ros_control.so">
            <robotNamespace>$(arg robot_namespace)</robotNamespace>
        </plugin>
    </gazebo> -->
  <!-- kp spring constant, kd damping constant -->
  <!-- <gazebo reference="front_left_wheel_link">
        <mu1>0.9</mu1>
        <mu2>0.7</mu2>
        <kp>1000000000.0</kp>
        <kd>0.0</kd>
        <minDepth>0.001</minDepth>
        <fdir1>1 0 0</fdir1>

    </gazebo>
    <gazebo reference="front_right_wheel_link">
        <mu1>0.9</mu1>
        <mu2>0.7</mu2>
        <kp>1000000000.0</kp>
        <kd>0.0</kd>
        <minDepth>0.001</minDepth>
        <fdir1>1 0 0</fdir1>

    </gazebo>
    <gazebo reference="rear_left_wheel_link">
        <mu1>0.9</mu1>
        <mu2>0.7</mu2>
        <kp>1000000000.0</kp>
        <kd>0.0</kd>
        <minDepth>0.001</minDepth>
        <fdir1>1 0 0</fdir1>

    </gazebo>
    <gazebo reference="rear_right_wheel_link">
        <mu1>0.9</mu1>
        <mu2>0.7</mu2>
        <kp>1000000000.0</kp>
        <kd>0.0</kd>
        <minDepth>0.001</minDepth>
        <fdir1>1 0 0</fdir1>
    </gazebo>
     -->
  <gazebo reference="base_link">
    <mu1>0.2</mu1>
    <mu2>0.2</mu2>
  </gazebo>
  <gazebo reference="front_right_wheel_link">
    <mu1>0.2</mu1>
    <mu2>0.2</mu2>
  </gazebo>
  <gazebo reference="front_left_wheel_link">
    <mu1>0.2</mu1>
    <mu2>0.2</mu2>
  </gazebo>
  <gazebo reference="rear_left_wheel_link">
    <mu1>0.2</mu1>
    <mu2>0.2</mu2>
  </gazebo>
  <gazebo reference="rear_right_wheel_link">
    <mu1>0.2</mu1>
    <mu2>0.2</mu2>
  </gazebo>
  <!-- <gazebo>
        <plugin name="skid_steer_drive_controller" filename="libgazebo_ros_skid_steer_drive.so">
            <updateRate>100.0</updateRate>
            <robotNamespace></robotNamespace>
            <leftFrontJoint>front_left_wheel</leftFrontJoint>
            <rightFrontJoint>front_right_wheel</rightFrontJoint>
            <leftRearJoint>rear_left_wheel</leftRearJoint>
            <rightRearJoint>rear_right_wheel</rightRearJoint>
            <wheelSeparation>4</wheelSeparation>
            <wheelDiameter>0.32918</wheelDiameter>
            <robotBaseFrame>base_link</robotBaseFrame>
            <torque>1000</torque>
            <commandTopic>cmd_vel</commandTopic>
            <broadcastTF>true</broadcastTF>
            <odometryTopic>odom</odometryTopic>
            <odometryFrame>odom</odometryFrame>
            <covariance_x>0.000100</covariance_x>
            <covariance_y>0.000100</covariance_y>
            <covariance_yaw>0.010000</covariance_yaw>
        </plugin>
    </gazebo> -->
  <!-- <gazebo>
        <plugin name="object_controller" filename="libgazebo_ros_planar_move.so">
            <commandTopic>cmd_vel</commandTopic>
            <odometryTopic>odom</odometryTopic>
            <odometryFrame>odom</odometryFrame>
            <odometryRate>20.0</odometryRate>
            <robotBaseFrame>base_footprint</robotBaseFrame>
        </plugin>
    </gazebo> -->
  <gazebo>
    <plugin filename="libgazebo_ros_diff_drive.so" name="diff_drive">
      <ros>
        <namespace>/</namespace>
        <remapping>cmd_vel:=cmd_vel</remapping>
        <remapping>odom:=odom</remapping>
      </ros>
      <update_rate>30</update_rate>
      <num_wheel_pairs>2</num_wheel_pairs>
      <left_joint>front_left_wheel</left_joint>
      <right_joint>front_right_wheel</right_joint>
      <left_joint>rear_left_wheel</left_joint>
      <right_joint>rear_right_wheel</right_joint>
      <wheel_separation>0.451</wheel_separation>
      <wheel_separation>0.451</wheel_separation>
      <wheel_diameter>0.08</wheel_diameter>
      <wheel_diameter>0.08</wheel_diameter>
      <max_wheel_torque>1000</max_wheel_torque>
      <max_wheel_acceleration>1.0</max_wheel_acceleration>
      <publish_odom>true</publish_odom>
      <publish_odom_tf>true</publish_odom_tf>
      <publish_wheel_tf>true</publish_wheel_tf>
      <odometry_frame>odom</odometry_frame>
      <robot_base_frame>base_link</robot_base_frame>
    </plugin>
  </gazebo>
</robot>
